{
 "cells": [
  {
   "cell_type": "markdown",
   "id": "7e95988e",
   "metadata": {},
   "source": [
    "# Pima Indians Onset of Diabetes Dataset"
   ]
  },
  {
   "cell_type": "code",
   "execution_count": null,
   "id": "05e879f1",
   "metadata": {},
   "outputs": [],
   "source": [
    "from keras.models import Sequential\n",
    "from keras.layers import Dense\n",
    "import numpy\n",
    "# fix random seed for reproducibility\n",
    "seed = 7\n",
    "numpy.random.seed(seed)"
   ]
  },
  {
   "cell_type": "code",
   "execution_count": 2,
   "id": "334cdf13",
   "metadata": {},
   "outputs": [],
   "source": [
    "# load pima indians dataset\n",
    "dataset = numpy.loadtxt(\"pima-indians-diabetes.csv\", delimiter=\",\")\n",
    "# split into input (X) and output (Y) variables\n",
    "X = dataset[:,0:8]\n",
    "Y = dataset[:,8]"
   ]
  },
  {
   "cell_type": "code",
   "execution_count": 6,
   "id": "eb61ca48",
   "metadata": {},
   "outputs": [],
   "source": [
    "from tensorflow.keras.models import Sequential\n",
    "from tensorflow.keras.layers import Conv2D, MaxPooling2D, Dense, Flatten\n",
    "\n",
    "# create model\n",
    "model = Sequential()\n",
    "model.add(Flatten())\n",
    "model.add(Dense(12, activation = 'relu'))\n",
    "model.add(Dense(8, activation = 'relu'))\n",
    "model.add(Dense(1, activation = 'sigmoid'))\n",
    "\n"
   ]
  },
  {
   "cell_type": "code",
   "execution_count": 9,
   "id": "5ade29f1",
   "metadata": {},
   "outputs": [],
   "source": [
    "# Compile model\n",
    "model.compile(loss= 'binary_crossentropy' , optimizer= 'adam', metrics=[ 'accuracy'])"
   ]
  },
  {
   "cell_type": "code",
   "execution_count": 11,
   "id": "f8f430b5",
   "metadata": {},
   "outputs": [
    {
     "name": "stdout",
     "output_type": "stream",
     "text": [
      "Epoch 1/150\n",
      "77/77 [==============================] - 1s 1ms/step - loss: 35.6970 - accuracy: 0.3490\n",
      "Epoch 2/150\n",
      "77/77 [==============================] - 0s 1ms/step - loss: 7.2609 - accuracy: 0.4284\n",
      "Epoch 3/150\n",
      "77/77 [==============================] - 0s 1ms/step - loss: 1.0017 - accuracy: 0.5924\n",
      "Epoch 4/150\n",
      "77/77 [==============================] - 0s 1ms/step - loss: 0.8448 - accuracy: 0.6159\n",
      "Epoch 5/150\n",
      "77/77 [==============================] - 0s 1ms/step - loss: 0.7954 - accuracy: 0.6107\n",
      "Epoch 6/150\n",
      "77/77 [==============================] - 0s 1ms/step - loss: 0.7382 - accuracy: 0.6341\n",
      "Epoch 7/150\n",
      "77/77 [==============================] - 0s 1ms/step - loss: 0.7404 - accuracy: 0.6198\n",
      "Epoch 8/150\n",
      "77/77 [==============================] - 0s 1ms/step - loss: 0.7041 - accuracy: 0.6367\n",
      "Epoch 9/150\n",
      "77/77 [==============================] - 0s 1ms/step - loss: 0.7004 - accuracy: 0.6471\n",
      "Epoch 10/150\n",
      "77/77 [==============================] - 0s 1ms/step - loss: 0.6838 - accuracy: 0.6406\n",
      "Epoch 11/150\n",
      "77/77 [==============================] - 0s 1ms/step - loss: 0.6860 - accuracy: 0.6523\n",
      "Epoch 12/150\n",
      "77/77 [==============================] - 0s 1ms/step - loss: 0.6729 - accuracy: 0.6406\n",
      "Epoch 13/150\n",
      "77/77 [==============================] - 0s 1ms/step - loss: 0.6540 - accuracy: 0.6602\n",
      "Epoch 14/150\n",
      "77/77 [==============================] - 0s 1ms/step - loss: 0.6514 - accuracy: 0.6589\n",
      "Epoch 15/150\n",
      "77/77 [==============================] - 0s 1ms/step - loss: 0.6404 - accuracy: 0.6654\n",
      "Epoch 16/150\n",
      "77/77 [==============================] - 0s 1ms/step - loss: 0.6332 - accuracy: 0.6680\n",
      "Epoch 17/150\n",
      "77/77 [==============================] - 0s 1ms/step - loss: 0.6220 - accuracy: 0.7031\n",
      "Epoch 18/150\n",
      "77/77 [==============================] - 0s 1ms/step - loss: 0.5980 - accuracy: 0.6953\n",
      "Epoch 19/150\n",
      "77/77 [==============================] - 0s 1ms/step - loss: 0.5899 - accuracy: 0.7122\n",
      "Epoch 20/150\n",
      "77/77 [==============================] - 0s 1ms/step - loss: 0.5883 - accuracy: 0.6901\n",
      "Epoch 21/150\n",
      "77/77 [==============================] - 0s 1ms/step - loss: 0.6052 - accuracy: 0.6888\n",
      "Epoch 22/150\n",
      "77/77 [==============================] - 0s 1ms/step - loss: 0.5794 - accuracy: 0.6888\n",
      "Epoch 23/150\n",
      "77/77 [==============================] - 0s 1ms/step - loss: 0.5648 - accuracy: 0.7174\n",
      "Epoch 24/150\n",
      "77/77 [==============================] - 0s 1ms/step - loss: 0.5937 - accuracy: 0.7122\n",
      "Epoch 25/150\n",
      "77/77 [==============================] - 0s 1ms/step - loss: 0.5664 - accuracy: 0.7044\n",
      "Epoch 26/150\n",
      "77/77 [==============================] - 0s 1ms/step - loss: 0.5626 - accuracy: 0.7240\n",
      "Epoch 27/150\n",
      "77/77 [==============================] - 0s 1ms/step - loss: 0.5870 - accuracy: 0.6966\n",
      "Epoch 28/150\n",
      "77/77 [==============================] - 0s 1ms/step - loss: 0.5603 - accuracy: 0.7188\n",
      "Epoch 29/150\n",
      "77/77 [==============================] - 0s 1ms/step - loss: 0.5562 - accuracy: 0.7096\n",
      "Epoch 30/150\n",
      "77/77 [==============================] - 0s 1ms/step - loss: 0.5450 - accuracy: 0.7422\n",
      "Epoch 31/150\n",
      "77/77 [==============================] - 0s 1ms/step - loss: 0.5884 - accuracy: 0.7188\n",
      "Epoch 32/150\n",
      "77/77 [==============================] - 0s 1ms/step - loss: 0.5661 - accuracy: 0.7096\n",
      "Epoch 33/150\n",
      "77/77 [==============================] - 0s 1ms/step - loss: 0.5597 - accuracy: 0.7240\n",
      "Epoch 34/150\n",
      "77/77 [==============================] - 0s 1ms/step - loss: 0.5469 - accuracy: 0.7227\n",
      "Epoch 35/150\n",
      "77/77 [==============================] - 0s 1ms/step - loss: 0.5395 - accuracy: 0.7461\n",
      "Epoch 36/150\n",
      "77/77 [==============================] - 0s 1ms/step - loss: 0.5432 - accuracy: 0.7461\n",
      "Epoch 37/150\n",
      "77/77 [==============================] - 0s 1ms/step - loss: 0.5539 - accuracy: 0.7292\n",
      "Epoch 38/150\n",
      "77/77 [==============================] - 0s 1ms/step - loss: 0.5555 - accuracy: 0.7188\n",
      "Epoch 39/150\n",
      "77/77 [==============================] - 0s 1ms/step - loss: 0.5541 - accuracy: 0.7057\n",
      "Epoch 40/150\n",
      "77/77 [==============================] - 0s 1ms/step - loss: 0.5418 - accuracy: 0.7357\n",
      "Epoch 41/150\n",
      "77/77 [==============================] - 0s 1ms/step - loss: 0.5683 - accuracy: 0.7018\n",
      "Epoch 42/150\n",
      "77/77 [==============================] - 0s 1ms/step - loss: 0.5580 - accuracy: 0.7253\n",
      "Epoch 43/150\n",
      "77/77 [==============================] - 0s 1ms/step - loss: 0.5367 - accuracy: 0.7331\n",
      "Epoch 44/150\n",
      "77/77 [==============================] - 0s 1ms/step - loss: 0.5213 - accuracy: 0.7526\n",
      "Epoch 45/150\n",
      "77/77 [==============================] - 0s 1ms/step - loss: 0.5446 - accuracy: 0.7383\n",
      "Epoch 46/150\n",
      "77/77 [==============================] - 0s 1ms/step - loss: 0.5341 - accuracy: 0.7409\n",
      "Epoch 47/150\n",
      "77/77 [==============================] - 0s 1ms/step - loss: 0.5405 - accuracy: 0.7448\n",
      "Epoch 48/150\n",
      "77/77 [==============================] - 0s 1ms/step - loss: 0.5320 - accuracy: 0.7474\n",
      "Epoch 49/150\n",
      "77/77 [==============================] - 0s 1ms/step - loss: 0.5318 - accuracy: 0.7422\n",
      "Epoch 50/150\n",
      "77/77 [==============================] - 0s 1ms/step - loss: 0.5429 - accuracy: 0.7409\n",
      "Epoch 51/150\n",
      "77/77 [==============================] - 0s 1ms/step - loss: 0.5394 - accuracy: 0.7253\n",
      "Epoch 52/150\n",
      "77/77 [==============================] - 0s 1ms/step - loss: 0.5225 - accuracy: 0.7409\n",
      "Epoch 53/150\n",
      "77/77 [==============================] - 0s 1ms/step - loss: 0.5240 - accuracy: 0.7448\n",
      "Epoch 54/150\n",
      "77/77 [==============================] - 0s 1ms/step - loss: 0.5190 - accuracy: 0.7370\n",
      "Epoch 55/150\n",
      "77/77 [==============================] - 0s 1ms/step - loss: 0.5387 - accuracy: 0.7161\n",
      "Epoch 56/150\n",
      "77/77 [==============================] - 0s 1ms/step - loss: 0.5321 - accuracy: 0.7435\n",
      "Epoch 57/150\n",
      "77/77 [==============================] - 0s 1ms/step - loss: 0.5279 - accuracy: 0.7188\n",
      "Epoch 58/150\n",
      "77/77 [==============================] - 0s 1ms/step - loss: 0.5362 - accuracy: 0.7344\n",
      "Epoch 59/150\n",
      "77/77 [==============================] - 0s 1ms/step - loss: 0.5283 - accuracy: 0.7474\n",
      "Epoch 60/150\n",
      "77/77 [==============================] - 0s 1ms/step - loss: 0.5261 - accuracy: 0.7448\n",
      "Epoch 61/150\n",
      "77/77 [==============================] - 0s 1ms/step - loss: 0.5480 - accuracy: 0.7409\n",
      "Epoch 62/150\n",
      "77/77 [==============================] - 0s 1ms/step - loss: 0.5409 - accuracy: 0.7318\n",
      "Epoch 63/150\n",
      "77/77 [==============================] - 0s 1ms/step - loss: 0.5145 - accuracy: 0.7526\n",
      "Epoch 64/150\n",
      "77/77 [==============================] - 0s 1ms/step - loss: 0.5086 - accuracy: 0.7357\n",
      "Epoch 65/150\n",
      "77/77 [==============================] - 0s 1ms/step - loss: 0.5193 - accuracy: 0.7435\n",
      "Epoch 66/150\n",
      "77/77 [==============================] - 0s 1ms/step - loss: 0.5214 - accuracy: 0.7422\n",
      "Epoch 67/150\n",
      "77/77 [==============================] - 0s 1ms/step - loss: 0.5243 - accuracy: 0.7500\n",
      "Epoch 68/150\n",
      "77/77 [==============================] - 0s 1ms/step - loss: 0.5132 - accuracy: 0.7461\n",
      "Epoch 69/150\n",
      "77/77 [==============================] - 0s 1ms/step - loss: 0.5306 - accuracy: 0.7240\n",
      "Epoch 70/150\n",
      "77/77 [==============================] - 0s 1ms/step - loss: 0.5122 - accuracy: 0.7591\n",
      "Epoch 71/150\n",
      "77/77 [==============================] - 0s 1ms/step - loss: 0.5065 - accuracy: 0.7552\n",
      "Epoch 72/150\n",
      "77/77 [==============================] - 0s 1ms/step - loss: 0.5047 - accuracy: 0.7682\n",
      "Epoch 73/150\n",
      "77/77 [==============================] - 0s 1ms/step - loss: 0.5086 - accuracy: 0.7448\n",
      "Epoch 74/150\n",
      "77/77 [==============================] - 0s 1ms/step - loss: 0.5166 - accuracy: 0.7539\n",
      "Epoch 75/150\n",
      "77/77 [==============================] - 0s 1ms/step - loss: 0.5051 - accuracy: 0.7591\n",
      "Epoch 76/150\n",
      "77/77 [==============================] - 0s 1ms/step - loss: 0.5122 - accuracy: 0.7591\n",
      "Epoch 77/150\n",
      "77/77 [==============================] - 0s 1ms/step - loss: 0.5239 - accuracy: 0.7305\n",
      "Epoch 78/150\n",
      "77/77 [==============================] - 0s 1ms/step - loss: 0.5010 - accuracy: 0.7630\n",
      "Epoch 79/150\n",
      "77/77 [==============================] - 0s 1ms/step - loss: 0.5063 - accuracy: 0.7526\n",
      "Epoch 80/150\n",
      "77/77 [==============================] - 0s 1ms/step - loss: 0.5037 - accuracy: 0.7526\n",
      "Epoch 81/150\n",
      "77/77 [==============================] - 0s 1ms/step - loss: 0.5140 - accuracy: 0.7422\n",
      "Epoch 82/150\n",
      "77/77 [==============================] - 0s 1ms/step - loss: 0.4990 - accuracy: 0.7643\n",
      "Epoch 83/150\n",
      "77/77 [==============================] - 0s 1ms/step - loss: 0.4871 - accuracy: 0.7630\n",
      "Epoch 84/150\n",
      "77/77 [==============================] - 0s 1ms/step - loss: 0.5160 - accuracy: 0.7513\n",
      "Epoch 85/150\n",
      "77/77 [==============================] - 0s 1ms/step - loss: 0.5238 - accuracy: 0.7513\n",
      "Epoch 86/150\n",
      "77/77 [==============================] - 0s 1ms/step - loss: 0.5121 - accuracy: 0.7422\n",
      "Epoch 87/150\n",
      "77/77 [==============================] - 0s 1ms/step - loss: 0.5125 - accuracy: 0.7383\n",
      "Epoch 88/150\n",
      "77/77 [==============================] - 0s 1ms/step - loss: 0.5046 - accuracy: 0.7409\n",
      "Epoch 89/150\n",
      "77/77 [==============================] - 0s 1ms/step - loss: 0.4947 - accuracy: 0.7669\n",
      "Epoch 90/150\n",
      "77/77 [==============================] - 0s 1ms/step - loss: 0.5060 - accuracy: 0.7500\n",
      "Epoch 91/150\n",
      "77/77 [==============================] - 0s 1ms/step - loss: 0.5029 - accuracy: 0.7630\n",
      "Epoch 92/150\n",
      "77/77 [==============================] - 0s 1ms/step - loss: 0.5154 - accuracy: 0.7513\n",
      "Epoch 93/150\n",
      "77/77 [==============================] - 0s 1ms/step - loss: 0.5176 - accuracy: 0.7591\n",
      "Epoch 94/150\n",
      "77/77 [==============================] - 0s 1ms/step - loss: 0.4931 - accuracy: 0.7682\n",
      "Epoch 95/150\n",
      "77/77 [==============================] - 0s 1ms/step - loss: 0.5210 - accuracy: 0.7552\n",
      "Epoch 96/150\n",
      "77/77 [==============================] - 0s 1ms/step - loss: 0.5125 - accuracy: 0.7513\n",
      "Epoch 97/150\n",
      "77/77 [==============================] - 0s 1ms/step - loss: 0.5014 - accuracy: 0.7552\n",
      "Epoch 98/150\n",
      "77/77 [==============================] - 0s 1ms/step - loss: 0.5121 - accuracy: 0.7591\n",
      "Epoch 99/150\n",
      "77/77 [==============================] - 0s 1ms/step - loss: 0.5170 - accuracy: 0.7565\n",
      "Epoch 100/150\n",
      "77/77 [==============================] - 0s 1ms/step - loss: 0.4932 - accuracy: 0.7591\n",
      "Epoch 101/150\n",
      "77/77 [==============================] - 0s 1ms/step - loss: 0.4899 - accuracy: 0.7552\n",
      "Epoch 102/150\n",
      "77/77 [==============================] - 0s 1ms/step - loss: 0.5027 - accuracy: 0.7669\n",
      "Epoch 103/150\n",
      "77/77 [==============================] - 0s 1ms/step - loss: 0.4934 - accuracy: 0.7682\n",
      "Epoch 104/150\n",
      "77/77 [==============================] - 0s 1ms/step - loss: 0.4890 - accuracy: 0.7643\n",
      "Epoch 105/150\n",
      "77/77 [==============================] - 0s 1ms/step - loss: 0.4933 - accuracy: 0.7656\n",
      "Epoch 106/150\n",
      "77/77 [==============================] - 0s 1ms/step - loss: 0.5003 - accuracy: 0.7526\n",
      "Epoch 107/150\n",
      "77/77 [==============================] - 0s 1ms/step - loss: 0.4937 - accuracy: 0.7656\n",
      "Epoch 108/150\n",
      "77/77 [==============================] - 0s 1ms/step - loss: 0.4968 - accuracy: 0.7695\n",
      "Epoch 109/150\n",
      "77/77 [==============================] - 0s 1ms/step - loss: 0.4893 - accuracy: 0.7591\n",
      "Epoch 110/150\n",
      "77/77 [==============================] - 0s 1ms/step - loss: 0.5061 - accuracy: 0.7643\n",
      "Epoch 111/150\n",
      "77/77 [==============================] - 0s 1ms/step - loss: 0.4952 - accuracy: 0.7604\n",
      "Epoch 112/150\n",
      "77/77 [==============================] - 0s 1ms/step - loss: 0.5235 - accuracy: 0.7513\n",
      "Epoch 113/150\n",
      "77/77 [==============================] - 0s 1ms/step - loss: 0.4896 - accuracy: 0.7565\n",
      "Epoch 114/150\n",
      "77/77 [==============================] - 0s 1ms/step - loss: 0.4885 - accuracy: 0.7630\n",
      "Epoch 115/150\n",
      "77/77 [==============================] - 0s 1ms/step - loss: 0.4985 - accuracy: 0.7461\n",
      "Epoch 116/150\n",
      "77/77 [==============================] - 0s 1ms/step - loss: 0.4833 - accuracy: 0.7708\n",
      "Epoch 117/150\n",
      "77/77 [==============================] - 0s 1ms/step - loss: 0.4845 - accuracy: 0.7747\n",
      "Epoch 118/150\n",
      "77/77 [==============================] - 0s 1ms/step - loss: 0.4932 - accuracy: 0.7604\n",
      "Epoch 119/150\n",
      "77/77 [==============================] - 0s 1ms/step - loss: 0.5040 - accuracy: 0.7292\n",
      "Epoch 120/150\n",
      "77/77 [==============================] - 0s 1ms/step - loss: 0.5029 - accuracy: 0.7565\n",
      "Epoch 121/150\n",
      "77/77 [==============================] - 0s 1ms/step - loss: 0.4874 - accuracy: 0.7682\n",
      "Epoch 122/150\n",
      "77/77 [==============================] - 0s 1ms/step - loss: 0.4779 - accuracy: 0.7656\n",
      "Epoch 123/150\n",
      "77/77 [==============================] - 0s 1ms/step - loss: 0.5040 - accuracy: 0.7539\n",
      "Epoch 124/150\n",
      "77/77 [==============================] - 0s 1ms/step - loss: 0.4998 - accuracy: 0.7604\n",
      "Epoch 125/150\n",
      "77/77 [==============================] - 0s 1ms/step - loss: 0.5044 - accuracy: 0.7539\n",
      "Epoch 126/150\n",
      "77/77 [==============================] - 0s 1ms/step - loss: 0.5012 - accuracy: 0.7461\n",
      "Epoch 127/150\n",
      "77/77 [==============================] - 0s 1ms/step - loss: 0.4871 - accuracy: 0.7682\n",
      "Epoch 128/150\n",
      "77/77 [==============================] - 0s 1ms/step - loss: 0.4939 - accuracy: 0.7682\n",
      "Epoch 129/150\n",
      "77/77 [==============================] - 0s 1ms/step - loss: 0.4782 - accuracy: 0.7747\n",
      "Epoch 130/150\n",
      "77/77 [==============================] - 0s 1ms/step - loss: 0.4811 - accuracy: 0.7669\n",
      "Epoch 131/150\n",
      "77/77 [==============================] - 0s 1ms/step - loss: 0.4799 - accuracy: 0.7682\n",
      "Epoch 132/150\n",
      "77/77 [==============================] - 0s 1ms/step - loss: 0.4798 - accuracy: 0.7682\n",
      "Epoch 133/150\n",
      "77/77 [==============================] - 0s 1ms/step - loss: 0.4862 - accuracy: 0.7565\n",
      "Epoch 134/150\n",
      "77/77 [==============================] - 0s 1ms/step - loss: 0.4931 - accuracy: 0.7747\n",
      "Epoch 135/150\n",
      "77/77 [==============================] - 0s 1ms/step - loss: 0.4777 - accuracy: 0.7826\n",
      "Epoch 136/150\n",
      "77/77 [==============================] - 0s 1ms/step - loss: 0.4943 - accuracy: 0.7708\n",
      "Epoch 137/150\n",
      "77/77 [==============================] - 0s 1ms/step - loss: 0.4729 - accuracy: 0.7643\n",
      "Epoch 138/150\n",
      "77/77 [==============================] - 0s 1ms/step - loss: 0.4824 - accuracy: 0.7747\n",
      "Epoch 139/150\n",
      "77/77 [==============================] - 0s 1ms/step - loss: 0.4777 - accuracy: 0.7721\n",
      "Epoch 140/150\n",
      "77/77 [==============================] - 0s 1ms/step - loss: 0.4833 - accuracy: 0.7643\n",
      "Epoch 141/150\n",
      "77/77 [==============================] - 0s 1ms/step - loss: 0.4800 - accuracy: 0.7747\n",
      "Epoch 142/150\n",
      "77/77 [==============================] - 0s 1ms/step - loss: 0.4904 - accuracy: 0.7643\n",
      "Epoch 143/150\n",
      "77/77 [==============================] - 0s 1ms/step - loss: 0.5057 - accuracy: 0.7539\n",
      "Epoch 144/150\n",
      "77/77 [==============================] - 0s 1ms/step - loss: 0.4926 - accuracy: 0.7721\n",
      "Epoch 145/150\n",
      "77/77 [==============================] - 0s 1ms/step - loss: 0.4779 - accuracy: 0.7760\n",
      "Epoch 146/150\n",
      "77/77 [==============================] - 0s 1ms/step - loss: 0.4833 - accuracy: 0.7669\n",
      "Epoch 147/150\n",
      "77/77 [==============================] - 0s 1ms/step - loss: 0.4947 - accuracy: 0.7643\n",
      "Epoch 148/150\n",
      "77/77 [==============================] - 0s 1ms/step - loss: 0.4747 - accuracy: 0.7734\n",
      "Epoch 149/150\n",
      "77/77 [==============================] - 0s 1ms/step - loss: 0.4893 - accuracy: 0.7656\n",
      "Epoch 150/150\n",
      "77/77 [==============================] - 0s 1ms/step - loss: 0.4802 - accuracy: 0.7799\n"
     ]
    },
    {
     "data": {
      "text/plain": [
       "<keras.callbacks.History at 0x271be9ede20>"
      ]
     },
     "execution_count": 11,
     "metadata": {},
     "output_type": "execute_result"
    }
   ],
   "source": [
    "# Fit the model\n",
    "model.fit(X, Y, epochs=150, batch_size=10)"
   ]
  },
  {
   "cell_type": "code",
   "execution_count": 12,
   "id": "6e35437e",
   "metadata": {},
   "outputs": [
    {
     "name": "stdout",
     "output_type": "stream",
     "text": [
      "24/24 [==============================] - 0s 1ms/step - loss: 0.4659 - accuracy: 0.7917\n",
      "accuracy: 79.17%\n"
     ]
    }
   ],
   "source": [
    "# evaluate the model\n",
    "scores = model.evaluate(X, Y)\n",
    "print(\"%s: %.2f%%\" % (model.metrics_names[1], scores[1]*100))"
   ]
  },
  {
   "cell_type": "markdown",
   "id": "5214786d",
   "metadata": {},
   "source": [
    "# Multiclass Classification Of Flower Species"
   ]
  },
  {
   "cell_type": "code",
   "execution_count": 16,
   "id": "de631447",
   "metadata": {},
   "outputs": [],
   "source": [
    "import numpy\n",
    "import pandas\n",
    "from keras.models import Sequential\n",
    "from keras.layers import Dense\n",
    "from keras.wrappers.scikit_learn import KerasClassifier\n",
    "from keras.utils import np_utils\n",
    "from sklearn.model_selection import cross_val_score\n",
    "from sklearn.model_selection import KFold\n",
    "from sklearn.preprocessing import LabelEncoder\n",
    "from sklearn.pipeline import Pipeline"
   ]
  },
  {
   "cell_type": "code",
   "execution_count": 17,
   "id": "a48f517f",
   "metadata": {},
   "outputs": [],
   "source": [
    "# fix random seed for reproducibility\n",
    "seed = 7\n",
    "numpy.random.seed(seed)"
   ]
  },
  {
   "cell_type": "code",
   "execution_count": 20,
   "id": "e2290874",
   "metadata": {},
   "outputs": [],
   "source": [
    "# load dataset\n",
    "dataframe = pandas.read_csv(\"iris.csv\", header=None)\n",
    "dataset = dataframe.values\n",
    "X = dataset[:,0:4]\n",
    "Y = dataset[:,4]"
   ]
  },
  {
   "cell_type": "code",
   "execution_count": 21,
   "id": "b49a12c2",
   "metadata": {},
   "outputs": [],
   "source": [
    "# encode class values as integers\n",
    "encoder = LabelEncoder()\n",
    "encoder.fit(Y)\n",
    "encoded_Y = encoder.transform(Y)\n",
    "# convert integers to dummy variables (i.e. one hot encoded)\n",
    "dummy_y = np_utils.to_categorical(encoded_Y)"
   ]
  },
  {
   "cell_type": "code",
   "execution_count": 24,
   "id": "31cf757e",
   "metadata": {},
   "outputs": [],
   "source": [
    "# define baseline model\n",
    "def baseline_model():\n",
    "# create model\n",
    " model = Sequential()\n",
    " model.add(Dense(4, input_dim=4, init= normal , activation= relu ))\n",
    " model.add(Dense(3, init= normal , activation= sigmoid ))\n",
    "# Compile model\n",
    " model.compile(loss= categorical_crossentropy , optimizer= adam , metrics=[ accuracy ])\n",
    " return model"
   ]
  },
  {
   "cell_type": "code",
   "execution_count": 25,
   "id": "b81e3e44",
   "metadata": {},
   "outputs": [
    {
     "name": "stderr",
     "output_type": "stream",
     "text": [
      "C:\\Users\\LocalAcc\\AppData\\Local\\Temp/ipykernel_12272/1436119445.py:1: DeprecationWarning: KerasClassifier is deprecated, use Sci-Keras (https://github.com/adriangb/scikeras) instead. See https://www.adriangb.com/scikeras/stable/migration.html for help migrating.\n",
      "  estimator = KerasClassifier(build_fn=baseline_model, nb_epoch=200, batch_size=5, verbose=0)\n"
     ]
    }
   ],
   "source": [
    "estimator = KerasClassifier(build_fn=baseline_model, nb_epoch=200, batch_size=5, verbose=0)"
   ]
  },
  {
   "cell_type": "code",
   "execution_count": 35,
   "id": "df53664e",
   "metadata": {},
   "outputs": [
    {
     "name": "stderr",
     "output_type": "stream",
     "text": [
      "C:\\Users\\LocalAcc\\AppData\\Local\\Temp/ipykernel_12272/2491290952.py:35: DeprecationWarning: KerasClassifier is deprecated, use Sci-Keras (https://github.com/adriangb/scikeras) instead. See https://www.adriangb.com/scikeras/stable/migration.html for help migrating.\n",
      "  estimator = KerasClassifier(build_fn=baseline_model, nb_epoch=200, batch_size=5, verbose=0)\n",
      "C:\\Users\\LocalAcc\\anaconda3\\lib\\site-packages\\sklearn\\model_selection\\_validation.py:615: FitFailedWarning: Estimator fit failed. The score on this train-test partition for these parameters will be set to nan. Details: \n",
      "Traceback (most recent call last):\n",
      "  File \"C:\\Users\\LocalAcc\\anaconda3\\lib\\site-packages\\sklearn\\model_selection\\_validation.py\", line 598, in _fit_and_score\n",
      "    estimator.fit(X_train, y_train, **fit_params)\n",
      "  File \"C:\\Users\\LocalAcc\\anaconda3\\lib\\site-packages\\keras\\wrappers\\scikit_learn.py\", line 236, in fit\n",
      "    return super(KerasClassifier, self).fit(x, y, **kwargs)\n",
      "  File \"C:\\Users\\LocalAcc\\anaconda3\\lib\\site-packages\\keras\\wrappers\\scikit_learn.py\", line 164, in fit\n",
      "    history = self.model.fit(x, y, **fit_args)\n",
      "  File \"C:\\Users\\LocalAcc\\anaconda3\\lib\\site-packages\\keras\\utils\\traceback_utils.py\", line 67, in error_handler\n",
      "    raise e.with_traceback(filtered_tb) from None\n",
      "  File \"C:\\Users\\LocalAcc\\anaconda3\\lib\\site-packages\\tensorflow\\python\\framework\\func_graph.py\", line 1147, in autograph_handler\n",
      "    raise e.ag_error_metadata.to_exception(e)\n",
      "ValueError: in user code:\n",
      "\n",
      "    File \"C:\\Users\\LocalAcc\\anaconda3\\lib\\site-packages\\keras\\engine\\training.py\", line 1021, in train_function  *\n",
      "        return step_function(self, iterator)\n",
      "    File \"C:\\Users\\LocalAcc\\anaconda3\\lib\\site-packages\\keras\\engine\\training.py\", line 1010, in step_function  **\n",
      "        outputs = model.distribute_strategy.run(run_step, args=(data,))\n",
      "    File \"C:\\Users\\LocalAcc\\anaconda3\\lib\\site-packages\\keras\\engine\\training.py\", line 1000, in run_step  **\n",
      "        outputs = model.train_step(data)\n",
      "    File \"C:\\Users\\LocalAcc\\anaconda3\\lib\\site-packages\\keras\\engine\\training.py\", line 860, in train_step\n",
      "        loss = self.compute_loss(x, y, y_pred, sample_weight)\n",
      "    File \"C:\\Users\\LocalAcc\\anaconda3\\lib\\site-packages\\keras\\engine\\training.py\", line 918, in compute_loss\n",
      "        return self.compiled_loss(\n",
      "    File \"C:\\Users\\LocalAcc\\anaconda3\\lib\\site-packages\\keras\\engine\\compile_utils.py\", line 201, in __call__\n",
      "        loss_value = loss_obj(y_t, y_p, sample_weight=sw)\n",
      "    File \"C:\\Users\\LocalAcc\\anaconda3\\lib\\site-packages\\keras\\losses.py\", line 141, in __call__\n",
      "        losses = call_fn(y_true, y_pred)\n",
      "    File \"C:\\Users\\LocalAcc\\anaconda3\\lib\\site-packages\\keras\\losses.py\", line 245, in call  **\n",
      "        return ag_fn(y_true, y_pred, **self._fn_kwargs)\n",
      "    File \"C:\\Users\\LocalAcc\\anaconda3\\lib\\site-packages\\keras\\losses.py\", line 1789, in categorical_crossentropy\n",
      "        return backend.categorical_crossentropy(\n",
      "    File \"C:\\Users\\LocalAcc\\anaconda3\\lib\\site-packages\\keras\\backend.py\", line 5083, in categorical_crossentropy\n",
      "        target.shape.assert_is_compatible_with(output.shape)\n",
      "\n",
      "    ValueError: Shapes (5, 4) and (5, 3) are incompatible\n",
      "\n",
      "\n",
      "  warnings.warn(\"Estimator fit failed. The score on this train-test\"\n",
      "C:\\Users\\LocalAcc\\anaconda3\\lib\\site-packages\\sklearn\\model_selection\\_validation.py:615: FitFailedWarning: Estimator fit failed. The score on this train-test partition for these parameters will be set to nan. Details: \n",
      "Traceback (most recent call last):\n",
      "  File \"C:\\Users\\LocalAcc\\anaconda3\\lib\\site-packages\\sklearn\\model_selection\\_validation.py\", line 598, in _fit_and_score\n",
      "    estimator.fit(X_train, y_train, **fit_params)\n",
      "  File \"C:\\Users\\LocalAcc\\anaconda3\\lib\\site-packages\\keras\\wrappers\\scikit_learn.py\", line 236, in fit\n",
      "    return super(KerasClassifier, self).fit(x, y, **kwargs)\n",
      "  File \"C:\\Users\\LocalAcc\\anaconda3\\lib\\site-packages\\keras\\wrappers\\scikit_learn.py\", line 164, in fit\n",
      "    history = self.model.fit(x, y, **fit_args)\n",
      "  File \"C:\\Users\\LocalAcc\\anaconda3\\lib\\site-packages\\keras\\utils\\traceback_utils.py\", line 67, in error_handler\n",
      "    raise e.with_traceback(filtered_tb) from None\n",
      "  File \"C:\\Users\\LocalAcc\\anaconda3\\lib\\site-packages\\tensorflow\\python\\framework\\func_graph.py\", line 1147, in autograph_handler\n",
      "    raise e.ag_error_metadata.to_exception(e)\n",
      "ValueError: in user code:\n",
      "\n",
      "    File \"C:\\Users\\LocalAcc\\anaconda3\\lib\\site-packages\\keras\\engine\\training.py\", line 1021, in train_function  *\n",
      "        return step_function(self, iterator)\n",
      "    File \"C:\\Users\\LocalAcc\\anaconda3\\lib\\site-packages\\keras\\engine\\training.py\", line 1010, in step_function  **\n",
      "        outputs = model.distribute_strategy.run(run_step, args=(data,))\n",
      "    File \"C:\\Users\\LocalAcc\\anaconda3\\lib\\site-packages\\keras\\engine\\training.py\", line 1000, in run_step  **\n",
      "        outputs = model.train_step(data)\n",
      "    File \"C:\\Users\\LocalAcc\\anaconda3\\lib\\site-packages\\keras\\engine\\training.py\", line 860, in train_step\n",
      "        loss = self.compute_loss(x, y, y_pred, sample_weight)\n",
      "    File \"C:\\Users\\LocalAcc\\anaconda3\\lib\\site-packages\\keras\\engine\\training.py\", line 918, in compute_loss\n",
      "        return self.compiled_loss(\n",
      "    File \"C:\\Users\\LocalAcc\\anaconda3\\lib\\site-packages\\keras\\engine\\compile_utils.py\", line 201, in __call__\n",
      "        loss_value = loss_obj(y_t, y_p, sample_weight=sw)\n",
      "    File \"C:\\Users\\LocalAcc\\anaconda3\\lib\\site-packages\\keras\\losses.py\", line 141, in __call__\n",
      "        losses = call_fn(y_true, y_pred)\n",
      "    File \"C:\\Users\\LocalAcc\\anaconda3\\lib\\site-packages\\keras\\losses.py\", line 245, in call  **\n",
      "        return ag_fn(y_true, y_pred, **self._fn_kwargs)\n",
      "    File \"C:\\Users\\LocalAcc\\anaconda3\\lib\\site-packages\\keras\\losses.py\", line 1789, in categorical_crossentropy\n",
      "        return backend.categorical_crossentropy(\n",
      "    File \"C:\\Users\\LocalAcc\\anaconda3\\lib\\site-packages\\keras\\backend.py\", line 5083, in categorical_crossentropy\n",
      "        target.shape.assert_is_compatible_with(output.shape)\n",
      "\n",
      "    ValueError: Shapes (None, 4) and (None, 3) are incompatible\n",
      "\n",
      "\n",
      "  warnings.warn(\"Estimator fit failed. The score on this train-test\"\n",
      "C:\\Users\\LocalAcc\\anaconda3\\lib\\site-packages\\sklearn\\model_selection\\_validation.py:615: FitFailedWarning: Estimator fit failed. The score on this train-test partition for these parameters will be set to nan. Details: \n",
      "Traceback (most recent call last):\n",
      "  File \"C:\\Users\\LocalAcc\\anaconda3\\lib\\site-packages\\sklearn\\model_selection\\_validation.py\", line 598, in _fit_and_score\n",
      "    estimator.fit(X_train, y_train, **fit_params)\n",
      "  File \"C:\\Users\\LocalAcc\\anaconda3\\lib\\site-packages\\keras\\wrappers\\scikit_learn.py\", line 236, in fit\n",
      "    return super(KerasClassifier, self).fit(x, y, **kwargs)\n",
      "  File \"C:\\Users\\LocalAcc\\anaconda3\\lib\\site-packages\\keras\\wrappers\\scikit_learn.py\", line 164, in fit\n",
      "    history = self.model.fit(x, y, **fit_args)\n",
      "  File \"C:\\Users\\LocalAcc\\anaconda3\\lib\\site-packages\\keras\\utils\\traceback_utils.py\", line 67, in error_handler\n",
      "    raise e.with_traceback(filtered_tb) from None\n",
      "  File \"C:\\Users\\LocalAcc\\anaconda3\\lib\\site-packages\\tensorflow\\python\\framework\\func_graph.py\", line 1147, in autograph_handler\n",
      "    raise e.ag_error_metadata.to_exception(e)\n",
      "ValueError: in user code:\n",
      "\n",
      "    File \"C:\\Users\\LocalAcc\\anaconda3\\lib\\site-packages\\keras\\engine\\training.py\", line 1021, in train_function  *\n",
      "        return step_function(self, iterator)\n",
      "    File \"C:\\Users\\LocalAcc\\anaconda3\\lib\\site-packages\\keras\\engine\\training.py\", line 1010, in step_function  **\n",
      "        outputs = model.distribute_strategy.run(run_step, args=(data,))\n",
      "    File \"C:\\Users\\LocalAcc\\anaconda3\\lib\\site-packages\\keras\\engine\\training.py\", line 1000, in run_step  **\n",
      "        outputs = model.train_step(data)\n",
      "    File \"C:\\Users\\LocalAcc\\anaconda3\\lib\\site-packages\\keras\\engine\\training.py\", line 860, in train_step\n",
      "        loss = self.compute_loss(x, y, y_pred, sample_weight)\n",
      "    File \"C:\\Users\\LocalAcc\\anaconda3\\lib\\site-packages\\keras\\engine\\training.py\", line 918, in compute_loss\n",
      "        return self.compiled_loss(\n",
      "    File \"C:\\Users\\LocalAcc\\anaconda3\\lib\\site-packages\\keras\\engine\\compile_utils.py\", line 201, in __call__\n",
      "        loss_value = loss_obj(y_t, y_p, sample_weight=sw)\n",
      "    File \"C:\\Users\\LocalAcc\\anaconda3\\lib\\site-packages\\keras\\losses.py\", line 141, in __call__\n",
      "        losses = call_fn(y_true, y_pred)\n",
      "    File \"C:\\Users\\LocalAcc\\anaconda3\\lib\\site-packages\\keras\\losses.py\", line 245, in call  **\n",
      "        return ag_fn(y_true, y_pred, **self._fn_kwargs)\n",
      "    File \"C:\\Users\\LocalAcc\\anaconda3\\lib\\site-packages\\keras\\losses.py\", line 1789, in categorical_crossentropy\n",
      "        return backend.categorical_crossentropy(\n",
      "    File \"C:\\Users\\LocalAcc\\anaconda3\\lib\\site-packages\\keras\\backend.py\", line 5083, in categorical_crossentropy\n",
      "        target.shape.assert_is_compatible_with(output.shape)\n",
      "\n",
      "    ValueError: Shapes (None, 4) and (None, 3) are incompatible\n",
      "\n",
      "\n",
      "  warnings.warn(\"Estimator fit failed. The score on this train-test\"\n",
      "C:\\Users\\LocalAcc\\anaconda3\\lib\\site-packages\\sklearn\\model_selection\\_validation.py:615: FitFailedWarning: Estimator fit failed. The score on this train-test partition for these parameters will be set to nan. Details: \n",
      "Traceback (most recent call last):\n",
      "  File \"C:\\Users\\LocalAcc\\anaconda3\\lib\\site-packages\\sklearn\\model_selection\\_validation.py\", line 598, in _fit_and_score\n",
      "    estimator.fit(X_train, y_train, **fit_params)\n",
      "  File \"C:\\Users\\LocalAcc\\anaconda3\\lib\\site-packages\\keras\\wrappers\\scikit_learn.py\", line 236, in fit\n",
      "    return super(KerasClassifier, self).fit(x, y, **kwargs)\n",
      "  File \"C:\\Users\\LocalAcc\\anaconda3\\lib\\site-packages\\keras\\wrappers\\scikit_learn.py\", line 164, in fit\n",
      "    history = self.model.fit(x, y, **fit_args)\n",
      "  File \"C:\\Users\\LocalAcc\\anaconda3\\lib\\site-packages\\keras\\utils\\traceback_utils.py\", line 67, in error_handler\n",
      "    raise e.with_traceback(filtered_tb) from None\n",
      "  File \"C:\\Users\\LocalAcc\\anaconda3\\lib\\site-packages\\tensorflow\\python\\framework\\func_graph.py\", line 1147, in autograph_handler\n",
      "    raise e.ag_error_metadata.to_exception(e)\n",
      "ValueError: in user code:\n",
      "\n",
      "    File \"C:\\Users\\LocalAcc\\anaconda3\\lib\\site-packages\\keras\\engine\\training.py\", line 1021, in train_function  *\n",
      "        return step_function(self, iterator)\n",
      "    File \"C:\\Users\\LocalAcc\\anaconda3\\lib\\site-packages\\keras\\engine\\training.py\", line 1010, in step_function  **\n",
      "        outputs = model.distribute_strategy.run(run_step, args=(data,))\n",
      "    File \"C:\\Users\\LocalAcc\\anaconda3\\lib\\site-packages\\keras\\engine\\training.py\", line 1000, in run_step  **\n",
      "        outputs = model.train_step(data)\n",
      "    File \"C:\\Users\\LocalAcc\\anaconda3\\lib\\site-packages\\keras\\engine\\training.py\", line 860, in train_step\n",
      "        loss = self.compute_loss(x, y, y_pred, sample_weight)\n",
      "    File \"C:\\Users\\LocalAcc\\anaconda3\\lib\\site-packages\\keras\\engine\\training.py\", line 918, in compute_loss\n",
      "        return self.compiled_loss(\n",
      "    File \"C:\\Users\\LocalAcc\\anaconda3\\lib\\site-packages\\keras\\engine\\compile_utils.py\", line 201, in __call__\n",
      "        loss_value = loss_obj(y_t, y_p, sample_weight=sw)\n",
      "    File \"C:\\Users\\LocalAcc\\anaconda3\\lib\\site-packages\\keras\\losses.py\", line 141, in __call__\n",
      "        losses = call_fn(y_true, y_pred)\n",
      "    File \"C:\\Users\\LocalAcc\\anaconda3\\lib\\site-packages\\keras\\losses.py\", line 245, in call  **\n",
      "        return ag_fn(y_true, y_pred, **self._fn_kwargs)\n",
      "    File \"C:\\Users\\LocalAcc\\anaconda3\\lib\\site-packages\\keras\\losses.py\", line 1789, in categorical_crossentropy\n",
      "        return backend.categorical_crossentropy(\n",
      "    File \"C:\\Users\\LocalAcc\\anaconda3\\lib\\site-packages\\keras\\backend.py\", line 5083, in categorical_crossentropy\n",
      "        target.shape.assert_is_compatible_with(output.shape)\n",
      "\n",
      "    ValueError: Shapes (None, 4) and (None, 3) are incompatible\n",
      "\n",
      "\n",
      "  warnings.warn(\"Estimator fit failed. The score on this train-test\"\n",
      "C:\\Users\\LocalAcc\\anaconda3\\lib\\site-packages\\sklearn\\model_selection\\_validation.py:615: FitFailedWarning: Estimator fit failed. The score on this train-test partition for these parameters will be set to nan. Details: \n",
      "Traceback (most recent call last):\n",
      "  File \"C:\\Users\\LocalAcc\\anaconda3\\lib\\site-packages\\sklearn\\model_selection\\_validation.py\", line 598, in _fit_and_score\n",
      "    estimator.fit(X_train, y_train, **fit_params)\n",
      "  File \"C:\\Users\\LocalAcc\\anaconda3\\lib\\site-packages\\keras\\wrappers\\scikit_learn.py\", line 236, in fit\n",
      "    return super(KerasClassifier, self).fit(x, y, **kwargs)\n",
      "  File \"C:\\Users\\LocalAcc\\anaconda3\\lib\\site-packages\\keras\\wrappers\\scikit_learn.py\", line 164, in fit\n",
      "    history = self.model.fit(x, y, **fit_args)\n",
      "  File \"C:\\Users\\LocalAcc\\anaconda3\\lib\\site-packages\\keras\\utils\\traceback_utils.py\", line 67, in error_handler\n",
      "    raise e.with_traceback(filtered_tb) from None\n",
      "  File \"C:\\Users\\LocalAcc\\anaconda3\\lib\\site-packages\\tensorflow\\python\\framework\\func_graph.py\", line 1147, in autograph_handler\n",
      "    raise e.ag_error_metadata.to_exception(e)\n",
      "ValueError: in user code:\n",
      "\n",
      "    File \"C:\\Users\\LocalAcc\\anaconda3\\lib\\site-packages\\keras\\engine\\training.py\", line 1021, in train_function  *\n",
      "        return step_function(self, iterator)\n",
      "    File \"C:\\Users\\LocalAcc\\anaconda3\\lib\\site-packages\\keras\\engine\\training.py\", line 1010, in step_function  **\n",
      "        outputs = model.distribute_strategy.run(run_step, args=(data,))\n",
      "    File \"C:\\Users\\LocalAcc\\anaconda3\\lib\\site-packages\\keras\\engine\\training.py\", line 1000, in run_step  **\n",
      "        outputs = model.train_step(data)\n",
      "    File \"C:\\Users\\LocalAcc\\anaconda3\\lib\\site-packages\\keras\\engine\\training.py\", line 860, in train_step\n",
      "        loss = self.compute_loss(x, y, y_pred, sample_weight)\n",
      "    File \"C:\\Users\\LocalAcc\\anaconda3\\lib\\site-packages\\keras\\engine\\training.py\", line 918, in compute_loss\n",
      "        return self.compiled_loss(\n",
      "    File \"C:\\Users\\LocalAcc\\anaconda3\\lib\\site-packages\\keras\\engine\\compile_utils.py\", line 201, in __call__\n",
      "        loss_value = loss_obj(y_t, y_p, sample_weight=sw)\n",
      "    File \"C:\\Users\\LocalAcc\\anaconda3\\lib\\site-packages\\keras\\losses.py\", line 141, in __call__\n",
      "        losses = call_fn(y_true, y_pred)\n",
      "    File \"C:\\Users\\LocalAcc\\anaconda3\\lib\\site-packages\\keras\\losses.py\", line 245, in call  **\n",
      "        return ag_fn(y_true, y_pred, **self._fn_kwargs)\n",
      "    File \"C:\\Users\\LocalAcc\\anaconda3\\lib\\site-packages\\keras\\losses.py\", line 1789, in categorical_crossentropy\n",
      "        return backend.categorical_crossentropy(\n",
      "    File \"C:\\Users\\LocalAcc\\anaconda3\\lib\\site-packages\\keras\\backend.py\", line 5083, in categorical_crossentropy\n",
      "        target.shape.assert_is_compatible_with(output.shape)\n",
      "\n",
      "    ValueError: Shapes (None, 4) and (None, 3) are incompatible\n",
      "\n",
      "\n",
      "  warnings.warn(\"Estimator fit failed. The score on this train-test\"\n",
      "C:\\Users\\LocalAcc\\anaconda3\\lib\\site-packages\\sklearn\\model_selection\\_validation.py:615: FitFailedWarning: Estimator fit failed. The score on this train-test partition for these parameters will be set to nan. Details: \n",
      "Traceback (most recent call last):\n",
      "  File \"C:\\Users\\LocalAcc\\anaconda3\\lib\\site-packages\\sklearn\\model_selection\\_validation.py\", line 598, in _fit_and_score\n",
      "    estimator.fit(X_train, y_train, **fit_params)\n",
      "  File \"C:\\Users\\LocalAcc\\anaconda3\\lib\\site-packages\\keras\\wrappers\\scikit_learn.py\", line 236, in fit\n",
      "    return super(KerasClassifier, self).fit(x, y, **kwargs)\n",
      "  File \"C:\\Users\\LocalAcc\\anaconda3\\lib\\site-packages\\keras\\wrappers\\scikit_learn.py\", line 164, in fit\n",
      "    history = self.model.fit(x, y, **fit_args)\n",
      "  File \"C:\\Users\\LocalAcc\\anaconda3\\lib\\site-packages\\keras\\utils\\traceback_utils.py\", line 67, in error_handler\n",
      "    raise e.with_traceback(filtered_tb) from None\n",
      "  File \"C:\\Users\\LocalAcc\\anaconda3\\lib\\site-packages\\tensorflow\\python\\framework\\func_graph.py\", line 1147, in autograph_handler\n",
      "    raise e.ag_error_metadata.to_exception(e)\n",
      "ValueError: in user code:\n",
      "\n",
      "    File \"C:\\Users\\LocalAcc\\anaconda3\\lib\\site-packages\\keras\\engine\\training.py\", line 1021, in train_function  *\n",
      "        return step_function(self, iterator)\n",
      "    File \"C:\\Users\\LocalAcc\\anaconda3\\lib\\site-packages\\keras\\engine\\training.py\", line 1010, in step_function  **\n",
      "        outputs = model.distribute_strategy.run(run_step, args=(data,))\n",
      "    File \"C:\\Users\\LocalAcc\\anaconda3\\lib\\site-packages\\keras\\engine\\training.py\", line 1000, in run_step  **\n",
      "        outputs = model.train_step(data)\n",
      "    File \"C:\\Users\\LocalAcc\\anaconda3\\lib\\site-packages\\keras\\engine\\training.py\", line 860, in train_step\n",
      "        loss = self.compute_loss(x, y, y_pred, sample_weight)\n",
      "    File \"C:\\Users\\LocalAcc\\anaconda3\\lib\\site-packages\\keras\\engine\\training.py\", line 918, in compute_loss\n",
      "        return self.compiled_loss(\n",
      "    File \"C:\\Users\\LocalAcc\\anaconda3\\lib\\site-packages\\keras\\engine\\compile_utils.py\", line 201, in __call__\n",
      "        loss_value = loss_obj(y_t, y_p, sample_weight=sw)\n",
      "    File \"C:\\Users\\LocalAcc\\anaconda3\\lib\\site-packages\\keras\\losses.py\", line 141, in __call__\n",
      "        losses = call_fn(y_true, y_pred)\n",
      "    File \"C:\\Users\\LocalAcc\\anaconda3\\lib\\site-packages\\keras\\losses.py\", line 245, in call  **\n",
      "        return ag_fn(y_true, y_pred, **self._fn_kwargs)\n",
      "    File \"C:\\Users\\LocalAcc\\anaconda3\\lib\\site-packages\\keras\\losses.py\", line 1789, in categorical_crossentropy\n",
      "        return backend.categorical_crossentropy(\n",
      "    File \"C:\\Users\\LocalAcc\\anaconda3\\lib\\site-packages\\keras\\backend.py\", line 5083, in categorical_crossentropy\n",
      "        target.shape.assert_is_compatible_with(output.shape)\n",
      "\n",
      "    ValueError: Shapes (None, 4) and (None, 3) are incompatible\n",
      "\n",
      "\n",
      "  warnings.warn(\"Estimator fit failed. The score on this train-test\"\n",
      "C:\\Users\\LocalAcc\\anaconda3\\lib\\site-packages\\sklearn\\model_selection\\_validation.py:615: FitFailedWarning: Estimator fit failed. The score on this train-test partition for these parameters will be set to nan. Details: \n",
      "Traceback (most recent call last):\n",
      "  File \"C:\\Users\\LocalAcc\\anaconda3\\lib\\site-packages\\sklearn\\model_selection\\_validation.py\", line 598, in _fit_and_score\n",
      "    estimator.fit(X_train, y_train, **fit_params)\n",
      "  File \"C:\\Users\\LocalAcc\\anaconda3\\lib\\site-packages\\keras\\wrappers\\scikit_learn.py\", line 236, in fit\n",
      "    return super(KerasClassifier, self).fit(x, y, **kwargs)\n",
      "  File \"C:\\Users\\LocalAcc\\anaconda3\\lib\\site-packages\\keras\\wrappers\\scikit_learn.py\", line 164, in fit\n",
      "    history = self.model.fit(x, y, **fit_args)\n",
      "  File \"C:\\Users\\LocalAcc\\anaconda3\\lib\\site-packages\\keras\\utils\\traceback_utils.py\", line 67, in error_handler\n",
      "    raise e.with_traceback(filtered_tb) from None\n",
      "  File \"C:\\Users\\LocalAcc\\anaconda3\\lib\\site-packages\\tensorflow\\python\\framework\\func_graph.py\", line 1147, in autograph_handler\n",
      "    raise e.ag_error_metadata.to_exception(e)\n",
      "ValueError: in user code:\n",
      "\n",
      "    File \"C:\\Users\\LocalAcc\\anaconda3\\lib\\site-packages\\keras\\engine\\training.py\", line 1021, in train_function  *\n",
      "        return step_function(self, iterator)\n",
      "    File \"C:\\Users\\LocalAcc\\anaconda3\\lib\\site-packages\\keras\\engine\\training.py\", line 1010, in step_function  **\n",
      "        outputs = model.distribute_strategy.run(run_step, args=(data,))\n",
      "    File \"C:\\Users\\LocalAcc\\anaconda3\\lib\\site-packages\\keras\\engine\\training.py\", line 1000, in run_step  **\n",
      "        outputs = model.train_step(data)\n",
      "    File \"C:\\Users\\LocalAcc\\anaconda3\\lib\\site-packages\\keras\\engine\\training.py\", line 860, in train_step\n",
      "        loss = self.compute_loss(x, y, y_pred, sample_weight)\n",
      "    File \"C:\\Users\\LocalAcc\\anaconda3\\lib\\site-packages\\keras\\engine\\training.py\", line 918, in compute_loss\n",
      "        return self.compiled_loss(\n",
      "    File \"C:\\Users\\LocalAcc\\anaconda3\\lib\\site-packages\\keras\\engine\\compile_utils.py\", line 201, in __call__\n",
      "        loss_value = loss_obj(y_t, y_p, sample_weight=sw)\n",
      "    File \"C:\\Users\\LocalAcc\\anaconda3\\lib\\site-packages\\keras\\losses.py\", line 141, in __call__\n",
      "        losses = call_fn(y_true, y_pred)\n",
      "    File \"C:\\Users\\LocalAcc\\anaconda3\\lib\\site-packages\\keras\\losses.py\", line 245, in call  **\n",
      "        return ag_fn(y_true, y_pred, **self._fn_kwargs)\n",
      "    File \"C:\\Users\\LocalAcc\\anaconda3\\lib\\site-packages\\keras\\losses.py\", line 1789, in categorical_crossentropy\n",
      "        return backend.categorical_crossentropy(\n",
      "    File \"C:\\Users\\LocalAcc\\anaconda3\\lib\\site-packages\\keras\\backend.py\", line 5083, in categorical_crossentropy\n",
      "        target.shape.assert_is_compatible_with(output.shape)\n",
      "\n",
      "    ValueError: Shapes (None, 4) and (None, 3) are incompatible\n",
      "\n",
      "\n",
      "  warnings.warn(\"Estimator fit failed. The score on this train-test\"\n",
      "C:\\Users\\LocalAcc\\anaconda3\\lib\\site-packages\\sklearn\\model_selection\\_validation.py:615: FitFailedWarning: Estimator fit failed. The score on this train-test partition for these parameters will be set to nan. Details: \n",
      "Traceback (most recent call last):\n",
      "  File \"C:\\Users\\LocalAcc\\anaconda3\\lib\\site-packages\\sklearn\\model_selection\\_validation.py\", line 598, in _fit_and_score\n",
      "    estimator.fit(X_train, y_train, **fit_params)\n",
      "  File \"C:\\Users\\LocalAcc\\anaconda3\\lib\\site-packages\\keras\\wrappers\\scikit_learn.py\", line 236, in fit\n",
      "    return super(KerasClassifier, self).fit(x, y, **kwargs)\n",
      "  File \"C:\\Users\\LocalAcc\\anaconda3\\lib\\site-packages\\keras\\wrappers\\scikit_learn.py\", line 164, in fit\n",
      "    history = self.model.fit(x, y, **fit_args)\n",
      "  File \"C:\\Users\\LocalAcc\\anaconda3\\lib\\site-packages\\keras\\utils\\traceback_utils.py\", line 67, in error_handler\n",
      "    raise e.with_traceback(filtered_tb) from None\n",
      "  File \"C:\\Users\\LocalAcc\\anaconda3\\lib\\site-packages\\tensorflow\\python\\framework\\func_graph.py\", line 1147, in autograph_handler\n",
      "    raise e.ag_error_metadata.to_exception(e)\n",
      "ValueError: in user code:\n",
      "\n",
      "    File \"C:\\Users\\LocalAcc\\anaconda3\\lib\\site-packages\\keras\\engine\\training.py\", line 1021, in train_function  *\n",
      "        return step_function(self, iterator)\n",
      "    File \"C:\\Users\\LocalAcc\\anaconda3\\lib\\site-packages\\keras\\engine\\training.py\", line 1010, in step_function  **\n",
      "        outputs = model.distribute_strategy.run(run_step, args=(data,))\n",
      "    File \"C:\\Users\\LocalAcc\\anaconda3\\lib\\site-packages\\keras\\engine\\training.py\", line 1000, in run_step  **\n",
      "        outputs = model.train_step(data)\n",
      "    File \"C:\\Users\\LocalAcc\\anaconda3\\lib\\site-packages\\keras\\engine\\training.py\", line 860, in train_step\n",
      "        loss = self.compute_loss(x, y, y_pred, sample_weight)\n",
      "    File \"C:\\Users\\LocalAcc\\anaconda3\\lib\\site-packages\\keras\\engine\\training.py\", line 918, in compute_loss\n",
      "        return self.compiled_loss(\n",
      "    File \"C:\\Users\\LocalAcc\\anaconda3\\lib\\site-packages\\keras\\engine\\compile_utils.py\", line 201, in __call__\n",
      "        loss_value = loss_obj(y_t, y_p, sample_weight=sw)\n",
      "    File \"C:\\Users\\LocalAcc\\anaconda3\\lib\\site-packages\\keras\\losses.py\", line 141, in __call__\n",
      "        losses = call_fn(y_true, y_pred)\n",
      "    File \"C:\\Users\\LocalAcc\\anaconda3\\lib\\site-packages\\keras\\losses.py\", line 245, in call  **\n",
      "        return ag_fn(y_true, y_pred, **self._fn_kwargs)\n",
      "    File \"C:\\Users\\LocalAcc\\anaconda3\\lib\\site-packages\\keras\\losses.py\", line 1789, in categorical_crossentropy\n",
      "        return backend.categorical_crossentropy(\n",
      "    File \"C:\\Users\\LocalAcc\\anaconda3\\lib\\site-packages\\keras\\backend.py\", line 5083, in categorical_crossentropy\n",
      "        target.shape.assert_is_compatible_with(output.shape)\n",
      "\n",
      "    ValueError: Shapes (None, 4) and (None, 3) are incompatible\n",
      "\n",
      "\n",
      "  warnings.warn(\"Estimator fit failed. The score on this train-test\"\n",
      "C:\\Users\\LocalAcc\\anaconda3\\lib\\site-packages\\sklearn\\model_selection\\_validation.py:615: FitFailedWarning: Estimator fit failed. The score on this train-test partition for these parameters will be set to nan. Details: \n",
      "Traceback (most recent call last):\n",
      "  File \"C:\\Users\\LocalAcc\\anaconda3\\lib\\site-packages\\sklearn\\model_selection\\_validation.py\", line 598, in _fit_and_score\n",
      "    estimator.fit(X_train, y_train, **fit_params)\n",
      "  File \"C:\\Users\\LocalAcc\\anaconda3\\lib\\site-packages\\keras\\wrappers\\scikit_learn.py\", line 236, in fit\n",
      "    return super(KerasClassifier, self).fit(x, y, **kwargs)\n",
      "  File \"C:\\Users\\LocalAcc\\anaconda3\\lib\\site-packages\\keras\\wrappers\\scikit_learn.py\", line 164, in fit\n",
      "    history = self.model.fit(x, y, **fit_args)\n",
      "  File \"C:\\Users\\LocalAcc\\anaconda3\\lib\\site-packages\\keras\\utils\\traceback_utils.py\", line 67, in error_handler\n",
      "    raise e.with_traceback(filtered_tb) from None\n",
      "  File \"C:\\Users\\LocalAcc\\anaconda3\\lib\\site-packages\\tensorflow\\python\\framework\\func_graph.py\", line 1147, in autograph_handler\n",
      "    raise e.ag_error_metadata.to_exception(e)\n",
      "ValueError: in user code:\n",
      "\n",
      "    File \"C:\\Users\\LocalAcc\\anaconda3\\lib\\site-packages\\keras\\engine\\training.py\", line 1021, in train_function  *\n",
      "        return step_function(self, iterator)\n",
      "    File \"C:\\Users\\LocalAcc\\anaconda3\\lib\\site-packages\\keras\\engine\\training.py\", line 1010, in step_function  **\n",
      "        outputs = model.distribute_strategy.run(run_step, args=(data,))\n",
      "    File \"C:\\Users\\LocalAcc\\anaconda3\\lib\\site-packages\\keras\\engine\\training.py\", line 1000, in run_step  **\n",
      "        outputs = model.train_step(data)\n",
      "    File \"C:\\Users\\LocalAcc\\anaconda3\\lib\\site-packages\\keras\\engine\\training.py\", line 860, in train_step\n",
      "        loss = self.compute_loss(x, y, y_pred, sample_weight)\n",
      "    File \"C:\\Users\\LocalAcc\\anaconda3\\lib\\site-packages\\keras\\engine\\training.py\", line 918, in compute_loss\n",
      "        return self.compiled_loss(\n",
      "    File \"C:\\Users\\LocalAcc\\anaconda3\\lib\\site-packages\\keras\\engine\\compile_utils.py\", line 201, in __call__\n",
      "        loss_value = loss_obj(y_t, y_p, sample_weight=sw)\n",
      "    File \"C:\\Users\\LocalAcc\\anaconda3\\lib\\site-packages\\keras\\losses.py\", line 141, in __call__\n",
      "        losses = call_fn(y_true, y_pred)\n",
      "    File \"C:\\Users\\LocalAcc\\anaconda3\\lib\\site-packages\\keras\\losses.py\", line 245, in call  **\n",
      "        return ag_fn(y_true, y_pred, **self._fn_kwargs)\n",
      "    File \"C:\\Users\\LocalAcc\\anaconda3\\lib\\site-packages\\keras\\losses.py\", line 1789, in categorical_crossentropy\n",
      "        return backend.categorical_crossentropy(\n",
      "    File \"C:\\Users\\LocalAcc\\anaconda3\\lib\\site-packages\\keras\\backend.py\", line 5083, in categorical_crossentropy\n",
      "        target.shape.assert_is_compatible_with(output.shape)\n",
      "\n",
      "    ValueError: Shapes (None, 4) and (None, 3) are incompatible\n",
      "\n",
      "\n",
      "  warnings.warn(\"Estimator fit failed. The score on this train-test\"\n"
     ]
    },
    {
     "name": "stdout",
     "output_type": "stream",
     "text": [
      "Accuracy: nan% (nan%)\n"
     ]
    },
    {
     "name": "stderr",
     "output_type": "stream",
     "text": [
      "C:\\Users\\LocalAcc\\anaconda3\\lib\\site-packages\\sklearn\\model_selection\\_validation.py:615: FitFailedWarning: Estimator fit failed. The score on this train-test partition for these parameters will be set to nan. Details: \n",
      "Traceback (most recent call last):\n",
      "  File \"C:\\Users\\LocalAcc\\anaconda3\\lib\\site-packages\\sklearn\\model_selection\\_validation.py\", line 598, in _fit_and_score\n",
      "    estimator.fit(X_train, y_train, **fit_params)\n",
      "  File \"C:\\Users\\LocalAcc\\anaconda3\\lib\\site-packages\\keras\\wrappers\\scikit_learn.py\", line 236, in fit\n",
      "    return super(KerasClassifier, self).fit(x, y, **kwargs)\n",
      "  File \"C:\\Users\\LocalAcc\\anaconda3\\lib\\site-packages\\keras\\wrappers\\scikit_learn.py\", line 164, in fit\n",
      "    history = self.model.fit(x, y, **fit_args)\n",
      "  File \"C:\\Users\\LocalAcc\\anaconda3\\lib\\site-packages\\keras\\utils\\traceback_utils.py\", line 67, in error_handler\n",
      "    raise e.with_traceback(filtered_tb) from None\n",
      "  File \"C:\\Users\\LocalAcc\\anaconda3\\lib\\site-packages\\tensorflow\\python\\framework\\func_graph.py\", line 1147, in autograph_handler\n",
      "    raise e.ag_error_metadata.to_exception(e)\n",
      "ValueError: in user code:\n",
      "\n",
      "    File \"C:\\Users\\LocalAcc\\anaconda3\\lib\\site-packages\\keras\\engine\\training.py\", line 1021, in train_function  *\n",
      "        return step_function(self, iterator)\n",
      "    File \"C:\\Users\\LocalAcc\\anaconda3\\lib\\site-packages\\keras\\engine\\training.py\", line 1010, in step_function  **\n",
      "        outputs = model.distribute_strategy.run(run_step, args=(data,))\n",
      "    File \"C:\\Users\\LocalAcc\\anaconda3\\lib\\site-packages\\keras\\engine\\training.py\", line 1000, in run_step  **\n",
      "        outputs = model.train_step(data)\n",
      "    File \"C:\\Users\\LocalAcc\\anaconda3\\lib\\site-packages\\keras\\engine\\training.py\", line 860, in train_step\n",
      "        loss = self.compute_loss(x, y, y_pred, sample_weight)\n",
      "    File \"C:\\Users\\LocalAcc\\anaconda3\\lib\\site-packages\\keras\\engine\\training.py\", line 918, in compute_loss\n",
      "        return self.compiled_loss(\n",
      "    File \"C:\\Users\\LocalAcc\\anaconda3\\lib\\site-packages\\keras\\engine\\compile_utils.py\", line 201, in __call__\n",
      "        loss_value = loss_obj(y_t, y_p, sample_weight=sw)\n",
      "    File \"C:\\Users\\LocalAcc\\anaconda3\\lib\\site-packages\\keras\\losses.py\", line 141, in __call__\n",
      "        losses = call_fn(y_true, y_pred)\n",
      "    File \"C:\\Users\\LocalAcc\\anaconda3\\lib\\site-packages\\keras\\losses.py\", line 245, in call  **\n",
      "        return ag_fn(y_true, y_pred, **self._fn_kwargs)\n",
      "    File \"C:\\Users\\LocalAcc\\anaconda3\\lib\\site-packages\\keras\\losses.py\", line 1789, in categorical_crossentropy\n",
      "        return backend.categorical_crossentropy(\n",
      "    File \"C:\\Users\\LocalAcc\\anaconda3\\lib\\site-packages\\keras\\backend.py\", line 5083, in categorical_crossentropy\n",
      "        target.shape.assert_is_compatible_with(output.shape)\n",
      "\n",
      "    ValueError: Shapes (None, 4) and (None, 3) are incompatible\n",
      "\n",
      "\n",
      "  warnings.warn(\"Estimator fit failed. The score on this train-test\"\n"
     ]
    }
   ],
   "source": [
    "# Multiclass Classification with the Iris Flowers Dataset\n",
    "import numpy\n",
    "import pandas\n",
    "from keras.models import Sequential\n",
    "from keras.layers import Dense\n",
    "from keras.wrappers.scikit_learn import KerasClassifier\n",
    "from keras.utils import np_utils\n",
    "from sklearn.model_selection import cross_val_score\n",
    "from sklearn.model_selection import KFold\n",
    "from sklearn.preprocessing import LabelEncoder\n",
    "from sklearn.pipeline import Pipeline\n",
    "# fix random seed for reproducibility\n",
    "seed = 7\n",
    "numpy.random.seed(seed)\n",
    "# load dataset\n",
    "dataframe = pandas.read_csv(\"iris.csv\", header=None)\n",
    "dataset = dataframe.values\n",
    "X = dataset[:,0:4]\n",
    "Y = dataset[:,4]\n",
    "# encode class values as integers\n",
    "encoder = LabelEncoder()\n",
    "encoder.fit(Y)\n",
    "encoded_Y = encoder.transform(Y)\n",
    "# convert integers to dummy variables (i.e. one hot encoded)\n",
    "dummy_y = np_utils.to_categorical(encoded_Y)\n",
    "# define baseline model\n",
    "def baseline_model():\n",
    "# create model\n",
    " model = Sequential()\n",
    " model.add(Dense(4, input_dim=4 , activation= 'relu' ))\n",
    " model.add(Dense(3, activation= 'sigmoid' ))\n",
    "# Compile model\n",
    " model.compile(loss= 'categorical_crossentropy' , optimizer= 'adam' , metrics=[ 'accuracy' ])\n",
    " return model\n",
    "estimator = KerasClassifier(build_fn=baseline_model, nb_epoch=200, batch_size=5, verbose=0)\n",
    "kfold = KFold(n_splits=10, shuffle=True, random_state=seed)\n",
    "results = cross_val_score(estimator, X, dummy_y, cv=kfold)\n",
    "print(\"Accuracy: %.2f%% (%.2f%%)\" % (results.mean()*100, results.std()*100))"
   ]
  },
  {
   "cell_type": "markdown",
   "id": "f9064dad",
   "metadata": {},
   "source": [
    "# Dropout Regularization For Neural Networks"
   ]
  },
  {
   "cell_type": "markdown",
   "id": "d2fc3689",
   "metadata": {},
   "source": [
    "Dropout is a regularization technique for neural network models proposed by Srivastava, et al.\n",
    "in their 2014 paper Dropout: A Simple Way to Prevent Neural Networks from Overfitting1.\n",
    "Dropout is a technique where randomly selected neurons are ignored during training. They\n",
    "are dropped-out randomly"
   ]
  },
  {
   "cell_type": "markdown",
   "id": "5fb3db7e",
   "metadata": {},
   "source": [
    "# Dropout Regularization in Keras"
   ]
  },
  {
   "cell_type": "code",
   "execution_count": 39,
   "id": "104aa632",
   "metadata": {},
   "outputs": [
    {
     "ename": "NameError",
     "evalue": "name 'standardize' is not defined",
     "output_type": "error",
     "traceback": [
      "\u001b[1;31m---------------------------------------------------------------------------\u001b[0m",
      "\u001b[1;31mNameError\u001b[0m                                 Traceback (most recent call last)",
      "\u001b[1;32m~\\AppData\\Local\\Temp/ipykernel_12272/2768071727.py\u001b[0m in \u001b[0;36m<module>\u001b[1;34m\u001b[0m\n\u001b[0;32m     40\u001b[0m \u001b[0mnumpy\u001b[0m\u001b[1;33m.\u001b[0m\u001b[0mrandom\u001b[0m\u001b[1;33m.\u001b[0m\u001b[0mseed\u001b[0m\u001b[1;33m(\u001b[0m\u001b[0mseed\u001b[0m\u001b[1;33m)\u001b[0m\u001b[1;33m\u001b[0m\u001b[1;33m\u001b[0m\u001b[0m\n\u001b[0;32m     41\u001b[0m \u001b[0mestimators\u001b[0m \u001b[1;33m=\u001b[0m \u001b[1;33m[\u001b[0m\u001b[1;33m]\u001b[0m\u001b[1;33m\u001b[0m\u001b[1;33m\u001b[0m\u001b[0m\n\u001b[1;32m---> 42\u001b[1;33m \u001b[0mestimators\u001b[0m\u001b[1;33m.\u001b[0m\u001b[0mappend\u001b[0m\u001b[1;33m(\u001b[0m\u001b[1;33m(\u001b[0m \u001b[0mstandardize\u001b[0m \u001b[1;33m,\u001b[0m \u001b[0mStandardScaler\u001b[0m\u001b[1;33m(\u001b[0m\u001b[1;33m)\u001b[0m\u001b[1;33m)\u001b[0m\u001b[1;33m)\u001b[0m\u001b[1;33m\u001b[0m\u001b[1;33m\u001b[0m\u001b[0m\n\u001b[0m\u001b[0;32m     43\u001b[0m estimators.append(( mlp , KerasClassifier(build_fn=create_baseline, nb_epoch=300,\n\u001b[0;32m     44\u001b[0m batch_size=16, verbose=0)))\n",
      "\u001b[1;31mNameError\u001b[0m: name 'standardize' is not defined"
     ]
    }
   ],
   "source": [
    "# Baseline Model on the Sonar Dataset\n",
    "import numpy\n",
    "import pandas\n",
    "from keras.models import Sequential\n",
    "from keras.layers import Dense\n",
    "from keras.layers import Dropout\n",
    "from keras.wrappers.scikit_learn import KerasClassifier\n",
    "from keras.constraints import maxnorm\n",
    "#from keras.optimizers import SGD\n",
    "from sklearn.model_selection import cross_val_score\n",
    "from sklearn.preprocessing import LabelEncoder\n",
    "from sklearn.model_selection import StratifiedKFold\n",
    "from sklearn.preprocessing import StandardScaler\n",
    "from sklearn.pipeline import Pipeline\n",
    "# fix random seed for reproducibility\n",
    "seed = 7\n",
    "numpy.random.seed(seed)\n",
    "# load dataset\n",
    "dataframe = pandas.read_csv(\"sonar.csv\", header=None)\n",
    "dataset = dataframe.values\n",
    "# split into input (X) and output (Y) variables\n",
    "X = dataset[:,0:60]\n",
    "Y = dataset[:,60]\n",
    "# encode class values as integers\n",
    "encoder = LabelEncoder()\n",
    "encoder.fit(Y)\n",
    "encoded_Y = encoder.transform(Y)\n",
    "# baseline\n",
    "def create_baseline():\n",
    "# create model\n",
    "    model = Sequential()\n",
    "    model.add(Dense(60, input_dim=60, init= normal , activation= relu ))\n",
    "    model.add(Dense(30, init= normal , activation= relu ))\n",
    "    model.add(Dense(1, init= normal , activation= sigmoid ))\n",
    "    # Compile model\n",
    "    sgd = SGD(lr=0.01, momentum=0.8, decay=0.0, nesterov=False)\n",
    "    model.compile(loss= binary_crossentropy , optimizer=sgd, metrics=[ accuracy ])\n",
    "    return model\n",
    "\n",
    "numpy.random.seed(seed)\n",
    "estimators = []\n",
    "estimators.append(( standardize , StandardScaler()))\n",
    "estimators.append(( mlp , KerasClassifier(build_fn=create_baseline, nb_epoch=300,\n",
    "batch_size=16, verbose=0)))\n",
    "pipeline = Pipeline(estimators)\n",
    "kfold = StratifiedKFold(n_splits=10, shuffle=True, random_state=seed)\n",
    "results = cross_val_score(pipeline, X, encoded_Y, cv=kfold)\n",
    "print(\"Baseline: %.2f%% (%.2f%%)\" % (results.mean()*100, results.std()*100))"
   ]
  },
  {
   "cell_type": "code",
   "execution_count": 41,
   "id": "965d6d07",
   "metadata": {},
   "outputs": [
    {
     "ename": "NameError",
     "evalue": "name 'gray' is not defined",
     "output_type": "error",
     "traceback": [
      "\u001b[1;31m---------------------------------------------------------------------------\u001b[0m",
      "\u001b[1;31mNameError\u001b[0m                                 Traceback (most recent call last)",
      "\u001b[1;32m~\\AppData\\Local\\Temp/ipykernel_12272/1261781348.py\u001b[0m in \u001b[0;36m<module>\u001b[1;34m\u001b[0m\n\u001b[0;32m      7\u001b[0m \u001b[1;31m# plot 4 images as gray scale\u001b[0m\u001b[1;33m\u001b[0m\u001b[1;33m\u001b[0m\u001b[0m\n\u001b[0;32m      8\u001b[0m \u001b[0mplt\u001b[0m\u001b[1;33m.\u001b[0m\u001b[0msubplot\u001b[0m\u001b[1;33m(\u001b[0m\u001b[1;36m221\u001b[0m\u001b[1;33m)\u001b[0m\u001b[1;33m\u001b[0m\u001b[1;33m\u001b[0m\u001b[0m\n\u001b[1;32m----> 9\u001b[1;33m \u001b[0mplt\u001b[0m\u001b[1;33m.\u001b[0m\u001b[0mimshow\u001b[0m\u001b[1;33m(\u001b[0m\u001b[0mX_train\u001b[0m\u001b[1;33m[\u001b[0m\u001b[1;36m0\u001b[0m\u001b[1;33m]\u001b[0m\u001b[1;33m,\u001b[0m \u001b[0mcmap\u001b[0m\u001b[1;33m=\u001b[0m\u001b[0mplt\u001b[0m\u001b[1;33m.\u001b[0m\u001b[0mget_cmap\u001b[0m\u001b[1;33m(\u001b[0m \u001b[0mgray\u001b[0m \u001b[1;33m)\u001b[0m\u001b[1;33m)\u001b[0m\u001b[1;33m\u001b[0m\u001b[1;33m\u001b[0m\u001b[0m\n\u001b[0m\u001b[0;32m     10\u001b[0m \u001b[0mplt\u001b[0m\u001b[1;33m.\u001b[0m\u001b[0msubplot\u001b[0m\u001b[1;33m(\u001b[0m\u001b[1;36m222\u001b[0m\u001b[1;33m)\u001b[0m\u001b[1;33m\u001b[0m\u001b[1;33m\u001b[0m\u001b[0m\n\u001b[0;32m     11\u001b[0m \u001b[0mplt\u001b[0m\u001b[1;33m.\u001b[0m\u001b[0mimshow\u001b[0m\u001b[1;33m(\u001b[0m\u001b[0mX_train\u001b[0m\u001b[1;33m[\u001b[0m\u001b[1;36m1\u001b[0m\u001b[1;33m]\u001b[0m\u001b[1;33m,\u001b[0m \u001b[0mcmap\u001b[0m\u001b[1;33m=\u001b[0m\u001b[0mplt\u001b[0m\u001b[1;33m.\u001b[0m\u001b[0mget_cmap\u001b[0m\u001b[1;33m(\u001b[0m \u001b[0mgray\u001b[0m \u001b[1;33m)\u001b[0m\u001b[1;33m)\u001b[0m\u001b[1;33m\u001b[0m\u001b[1;33m\u001b[0m\u001b[0m\n",
      "\u001b[1;31mNameError\u001b[0m: name 'gray' is not defined"
     ]
    },
    {
     "data": {
      "image/png": "iVBORw0KGgoAAAANSUhEUgAAAMsAAACGCAYAAABzPX6BAAAAOXRFWHRTb2Z0d2FyZQBNYXRwbG90bGliIHZlcnNpb24zLjQuMywgaHR0cHM6Ly9tYXRwbG90bGliLm9yZy/MnkTPAAAACXBIWXMAAAsTAAALEwEAmpwYAAAIkklEQVR4nO3dXYxUdxnH8e/PUhKLpFR5sVZXq0EpNZLQtWJrLGisXbRpmnABvpCQJhtMNepFo9GkeqnpjakvENKQphelNy21JrSl0SiNFdtdQ2HbVANtVYQEKIRGalTw8eKcrcOyL8/s/ufMjvw+yYSZc/7/fc6B+THnzMw+RxGBmU3tLd3eALNe4bCYJTksZkkOi1mSw2KW5LCYJU0ZFknbJR2TNDLBekm6V9JBSfslrWxZd4ukP9brvl1yw82alnlluR+4ZZL1A8DS+jYIbAGQdAnw03r9cmCDpOUz2VizbpoyLBGxBzg5yZDbgAeishdYIOlK4HrgYES8HBH/Ah6qx5r1pBLnLFcBf215fLheNtFys540p8DP0DjLYpLl4/8QaZDqMI558+Zdt2zZsgKbZnah4eHhExGxqN15JcJyGHhPy+N3A0eAuRMsH1dEbAO2AfT398fQ0FCBTTO7kKQ/T2deicOwx4CN9btiq4DTEXEUeA5YKulqSXOB9fVYs5405SuLpB3AamChpMPA94BLASJiK7ALWAscBN4ANtXrzkr6KvAkcAmwPSJe6MA+mDViyrBExIYp1gdw5wTrdlGFyazn+RN8sySHxSzJYTFLcljMkhwWsySHxSzJYTFLcljMkhwWsySHxSzJYTFLcljMkhwWsySHxSzJYTFLcljMklJhmapZnqS7JO2rbyOSzkl6e73uVUkH6nX+xXrrWZlfKx5tlvcZquYUz0l6LCJeHB0TEfcA99TjbwW+GRGtvcbWRMSJoltu1rDMK0u7zfI2ADtKbJzZbJIJS7pZnqTLqFq9PtyyOIDdkobr3mBmPSnTN6ydZnm3Ar8dcwh2Y0QckbQYeErSS3VL2POLtDTZ6+vrS2yWWbMyrywTNdEbz3rGHIJFxJH6z2PATqrDugtExLaI6I+I/kWL2m4WaNZxmbCkmuVJuhy4Cfh5y7J5kuaP3gduBsa9dIXZbJfpGzZuszxJm+v1W+uhtwO7I+JMy/QlwE5Jo7UejIgnSu6AWVNU9cibXdzr2DpJ0nBE9Lc7z5/gmyU5LGZJDotZksNiluSwmCU5LGZJDotZksNiluSwmCU5LGZJDotZksNiluSwmCU5LGZJDotZksNillSqyd5qSadbGu3dnZ1r1iuKNNmrPR0Rn5/mXLNZrxNN9krNNZtVSjbZ+7ik5yU9LunaNuciaVDSkKSh48ePJzbLrFmZsGSa7P0BeG9ErAB+DDzaxtxqofuG2SxXpMleRLweEX+v7+8CLpW0MDPXrFcUabIn6Z2qm4NJur7+ua9l5pr1ilJN9tYBX5F0FvgHsD6qhmTjzu3Qvph1lJvs2UXHTfbMOsxhMUtyWMySHBazJIfFLMlhMUtyWMySHBazJIfFLMlhMUtyWMySHBazJIfFLMlhMUtyWMySSvUN+6Kk/fXtGUkrWta9KulA3U/Mv6RiPatU37BXgJsi4pSkAWAb8LGW9Wsi4kTB7TZrXJG+YRHxTEScqh/upWpMYfZ/pWTfsFF3AI+3PA5gt6RhSYPtb6LZ7DDlYRht9P6StIYqLJ9oWXxjRByRtBh4StJLEbFnnLmDwCBAX19fYrPMmlWkbxiApI8A9wG3RcRro8sj4kj95zFgJ9Vh3QXcZM9mu1J9w/qAR4AvR8SfWpbPkzR/9D5wMzBSauPNmlSqb9jdwDuAn9W99s7WrWaWADvrZXOAByPiiY7siVmHuW+YXXTcN8yswxwWsySHxSzJYTFLcljMkhwWsySHxSzJYTFLcljMkhwWsySHxSzJYTFLcljMkhwWsySHxSzJYTFLKtVkT5Lurdfvl7QyO9esV0wZlpYmewPAcmCDpOVjhg0AS+vbILCljblmPaFIk7368QNR2QsskHRlcq5ZTyjVZG+iMe026DObtUo12ZtoTDsN+t5ssgf8U1I3WiYtBLrRk7lbdbtZu5v7/KHpTMqEJdNkb6IxcxNzgarJHlVDcSQNTaf7xkxdbHW7Wbvb+zydeUWa7NWPN9bviq0CTkfE0eRcs55QqsneLmAtcBB4A9g02dyO7IlZh2UOw4iIXVSBaF22teV+AHdm5yZsa3N8KRdb3W7W7rl9npUdKc1mI3/dxSypa2GZyVdoGqg94TUyO1m3ZdxHJZ2TtK5E3WxtSavra3++IOk3TdSVdLmkX0h6vq67qVDd7ZKOTfQRxLSeXxHR+I3qZP8Q8H6qt5efB5aPGbOW6gpiAlYBv2+w9g3AFfX9gRK1M3Vbxv2K6jxvXYP7vAB4EeirHy9uqO53gB/W9xcBJ4G5BWp/ElgJjEywvu3nV7deWWbyFZqO147OXCMz+9WfrwEPA8cK1Gyn9heARyLiL/DmxaeaqBvAfFXXJXkbVVjOzrRwVFeXOznJkLafX90Ky0y+QtNE7VZjr5HZsbqSrgJuB7ZSVmafPwhcIenX9fU/NzZU9yfANVQfVh8Avh4R/ylQu8S2nSf11nEHzOQrNE3UrgaOf43MTtb9EfCtiDhXXwCqlEztOcB1wKeBtwK/k7Q3Wq7k1qG6nwX2AZ8CPkB13dGnI+L1GdQttW3n6VZYZvIVmiZqt14jcyBarpHZ4br9wEN1UBYCayWdjYhHG6h9GDgREWeAM5L2ACuAmYQlU3cT8IOoTiQOSnoFWAY8O4O6pbbtfCVOIKdx8jUHeBm4mv+d+F07ZsznOP8E7NkGa/dRfRvhhib3ecz4+yl3gp/Z52uAX9ZjL6O69ueHG6i7Bfh+fX8J8DdgYaH9fh8Tn+C3/fzqeDAm2ZG1VP9rHQK+Wy/bDGyu74vqF8cOUR3L9jdY+z7gFNXhwT5gqIm6Y8YWC0u2NnAX1TtiI8A3Gvq7fhewu/43HgG+VKjuDuAo8G+qV5E7Zvr88if4Zkn+BN8syWExS3JYzJIcFrMkh8UsyWExS3JYzJIcFrOk/wLlLayGHk8RLgAAAABJRU5ErkJggg==\n",
      "text/plain": [
       "<Figure size 432x288 with 1 Axes>"
      ]
     },
     "metadata": {
      "needs_background": "light"
     },
     "output_type": "display_data"
    }
   ],
   "source": [
    "# Plot ad hoc mnist instances\n",
    "from keras.datasets import mnist\n",
    "import cv2\n",
    "import matplotlib.pyplot as plt\n",
    "# load (downloaded if needed) the MNIST dataset\n",
    "(X_train, y_train), (X_test, y_test) = mnist.load_data()\n",
    "# plot 4 images as gray scale\n",
    "plt.subplot(221)\n",
    "plt.imshow(X_train[0], cmap=plt.get_cmap( gray ))\n",
    "plt.subplot(222)\n",
    "plt.imshow(X_train[1], cmap=plt.get_cmap( gray ))\n",
    "plt.subplot(223)\n",
    "plt.imshow(X_train[2], cmap=plt.get_cmap( gray ))\n",
    "plt.subplot(224)\n",
    "plt.imshow(X_train[3], cmap=plt.get_cmap( gray ))\n",
    "# show the plot\n",
    "plt.show()"
   ]
  },
  {
   "cell_type": "code",
   "execution_count": null,
   "id": "f89488a5",
   "metadata": {},
   "outputs": [],
   "source": []
  }
 ],
 "metadata": {
  "kernelspec": {
   "display_name": "Python 3 (ipykernel)",
   "language": "python",
   "name": "python3"
  },
  "language_info": {
   "codemirror_mode": {
    "name": "ipython",
    "version": 3
   },
   "file_extension": ".py",
   "mimetype": "text/x-python",
   "name": "python",
   "nbconvert_exporter": "python",
   "pygments_lexer": "ipython3",
   "version": "3.9.7"
  }
 },
 "nbformat": 4,
 "nbformat_minor": 5
}
